Workbook

Sheet 拾い出し
A1: 名称 （列幅17） | B1: 列 | C1: 備考 (9） | D1: 規格 （14.5） | E1: 規格 (8) | F1: 規格(入数) (6.75) | G1: 階 (2.75) | H1: 数量 (4) | I1: 在庫 (5.5) | J1: 発注 (4) | K1: 単位 (2.75) | L1: 印（日付確定したら） | M1: 納品日 (6.5) | N1: 使用建材と空白行 | O1: 納品場所 (9) | P1: 納品備考 （20） | Q1: 材料ｺｰﾄﾞ | R1: 材料仕入/外注 | S1: 発注業者 （17） | T1: 担当者 | U1: 業者コード | V1: 発注予定日 | W1: 元番号 | X1: リンク
A2: 遣り方用 貫 | D2: 杉 1ト 13’×30×05 | K2: 丁 | N2: × | Q2: 10001 | R2: 材 | S2: 渡辺製材所 | U2: WATANABE | V2: =IFERROR(IF(M2="","",M2-20),M2) | W2: =ROW() -> 2
A3: 遣り方用 杭 | D3: 4尺 | K3: 丁 | N3: × | Q3: 10002 | R3: 材 | S3: 渡辺製材所 | U3: WATANABE | V3: =IFERROR(IF(M3="","",M3-20),M3) | W3: =ROW() -> 3
Q4: 10003 | V4: =IFERROR(IF(M4="","",M4-20),M4) | W4: =ROW() -> 4
A5: スタイロフォーム | D5: t15 3’×6' | F5: 基礎立上断熱 | H5: 1+少 | J5: 1 | K5: 枚 | L5: z | M5: 46122 | N5: ○ | O5: 作業場 | Q5: 10004 | R5: 材 | S5: 岡田電気産業 | T5: 大槻 | U5: OKADA | V5: =IFERROR(IF(M5="","",M5-20),M5) -> 46102 | W5: =ROW() -> 5
A6: ミラフォーム | D6: t30 3’×6' | F6: 基礎土間断熱 | J6: 2 | K6: 枚 | L6: z | M6: 46122 | N6: ○ | O6: 作業場 | Q6: 10005 | R6: 材 | S6: 岡田電気産業 | T6: 大槻 | U6: OKADA | V6: =IFERROR(IF(M6="","",M6-20),M6) -> 46102 | W6: =ROW() -> 6
A7: ミラフォーム | D7: t30 3’×6' | F7: 床下玄関立上り | H7: 1 | J7: 3 | K7: 枚 | L7: z | M7: 46122 | N7: ○ | O7: 作業場 | Q7: 10006 | R7: 材 | S7: 岡田電気産業 | T7: 大槻 | U7: OKADA | V7: =IFERROR(IF(M7="","",M7-20),M7) -> 46102 | W7: =ROW() -> 7
A8: ミラフォーム | D8: t30 3’×6' | F8: UB土間+立上り | H8: 4 | J8: 4 | K8: 枚 | L8: z | M8: 46122 | N8: ○ | O8: 作業場 | Q8: 10007 | R8: 材 | S8: 岡田電気産業 | T8: 大槻 | U8: OKADA | V8: =IFERROR(IF(M8="","",M8-20),M8) -> 46102 | W8: =ROW() -> 8
A9: ミラフォーム | C9: UB立上り | D9: t50 3’×6' | K9: 枚 | N9: × | O9: 作業場 | Q9: 10008 | R9: 材 | S9: 岡田電気産業 | T9: 大槻 | U9: OKADA | V9: =IFERROR(IF(M9="","",M9-20),M9) | W9: =ROW() -> 9
A10: スタイロフォーム | D10: t15 3’×6’ | F10: UB窓枠 | H10: 1 | J10: 1 | K10: 枚 | L10: z | M10: 46122 | N10: ○ | O10: 作業場 | Q10: 10009 | R10: 材 | S10: 岡田電気産業 | T10: 大槻 | U10: OKADA | V10: =IFERROR(IF(M10="","",M10-20),M10) -> 46102 | W10: =ROW() -> 10
N11: ○ | Q11: 10010 | V11: =IFERROR(IF(M11="","",M11-20),M11) | W11: =ROW() -> 11
A12: プレカット材 | D12: 基礎ﾊﾟｯｷﾝ・床束 | E12: ・金物 | J12: 1 | K12: 式 | L12: z | M12: 46167 | N12: ○ | O12: 現場 | P12: 1便目：床組材・金物他 | Q12: 10011 | R12: 材 | S12: ﾀｶｶﾂ建材 ﾌﾟﾚｶｯﾄ | T12: 鈴木 | U12: TAKAKATSUP | V12: =IFERROR(IF(M12="","",M12-20),M12) -> 46147 | W12: =ROW() -> 12
A13: プレカット材 | K13: 式 | N13: × | O13: 現場 | Q13: 10012 | R13: 材 | S13: ﾀｶｶﾂ建材 ﾌﾟﾚｶｯﾄ | T13: 鈴木 | U13: TAKAKATSUP | V13: =IFERROR(IF(M13="","",M13-20),M13) | W13: =ROW() -> 13
A14: 基礎ﾊﾟｯｷﾝロング | D14: KP-L102 | K14: 本 | N14: × | O14: 現場 | Q14: 10013 | R14: 材 | S14: ﾀｶｶﾂ建材 ﾌﾟﾚｶｯﾄ | T14: 鈴木 | U14: TAKAKATSUP | V14: =IFERROR(IF(M14="","",M14-20),M14) | W14: =ROW() -> 14
A15: 気密ﾊﾟｯｷﾝロング | D15: KPK-N105 | K15: 本 | N15: × | O15: 現場 | Q15: 10014 | R15: 材 | S15: ﾀｶｶﾂ建材 ﾌﾟﾚｶｯﾄ | T15: 鈴木 | U15: TAKAKATSUP | V15: =IFERROR(IF(M15="","",M15-20),M15) | W15: =ROW() -> 15
A16: 針葉樹 構造用合板 | C16: 屋根 | D16: t12 3’×6' | F16: 屋根 | G16: 2F | K16: 枚 | N16: × | O16: 現場 | Q16: 10015 | R16: 材 | S16: ﾀｶｶﾂ建材 ﾌﾟﾚｶｯﾄ | T16: 鈴木 | U16: TAKAKATSUP | V16: =IFERROR(IF(M16="","",M16-20),M16) | W16: =ROW() -> 16
A17: 針葉樹 構造用合板 | C17: 屋根 | D17: t12 3’×6' | F17: 屋根 | G17: 1F | K17: 枚 | N17: × | O17: 現場 | Q17: 10016 | R17: 材 | S17: ﾀｶｶﾂ建材 ﾌﾟﾚｶｯﾄ | T17: 鈴木 | U17: TAKAKATSUP | V17: =IFERROR(IF(M17="","",M17-20),M17) | W17: =ROW() -> 17
A18: ネダレス 実なし | D18: t24 3’×6’ | G18: 2F | K18: 枚 | N18: × | O18: 現場 | Q18: 10017 | R18: 材 | S18: ﾀｶｶﾂ建材 ﾌﾟﾚｶｯﾄ | T18: 鈴木 | U18: TAKAKATSUP | V18: =IFERROR(IF(M18="","",M18-20),M18) | W18: =ROW() -> 18
A19: ネダレス 実なし | D19: t24 3’×6’ | G19: 1F | K19: 枚 | N19: × | O19: 現場 | Q19: 10018 | R19: 材 | S19: ﾀｶｶﾂ建材 ﾌﾟﾚｶｯﾄ | T19: 鈴木 | U19: TAKAKATSUP | V19: =IFERROR(IF(M19="","",M19-20),M19) | W19: =ROW() -> 19
A20: ネダレス ｽﾍﾟｰｻｰ | D20: t24 3’×6’ | K20: 枚 | N20: × | O20: 現場 | Q20: 10019 | R20: 材 | S20: ﾀｶｶﾂ建材 ﾌﾟﾚｶｯﾄ | T20: 鈴木 | U20: TAKAKATSUP | V20: =IFERROR(IF(M20="","",M20-20),M20) | W20: =ROW() -> 20
A21: ミラフォーム | C21: 2重貼り・2階床 | D21: t50 3’×6’ | G21: 2F | H21: 5 | I21: 2 | J21: 5 | K21: 枚 | L21: z | M21: 46167 | N21: ○ | O21: 現場 | Q21: 10020 | R21: 材 | S21: ﾀｶｶﾂ建材 ﾌﾟﾚｶｯﾄ | T21: 鈴木 | U21: TAKAKATSUP | V21: =IFERROR(IF(M21="","",M21-20),M21) -> 46147 | W21: =ROW() -> 21
A22: ミラフォーム | C22: 1階床 | D22: t65 3’×6’ | G22: 1F | K22: 枚 | L22: z | M22: 46167 | N22: ○ | O22: 現場 | Q22: 10021 | R22: 材 | S22: ﾀｶｶﾂ建材 ﾌﾟﾚｶｯﾄ | T22: 鈴木 | U22: TAKAKATSUP | V22: =IFERROR(IF(M22="","",M22-20),M22) -> 46147 | W22: =ROW() -> 22
A23: 断熱材受金具 | D23: t65用 | K23: 箱 | N23: × | O23: 現場 | Q23: 10022 | R23: 材 | S23: ﾀｶｶﾂ建材 ﾌﾟﾚｶｯﾄ | T23: 鈴木 | U23: TAKAKATSUP | V23: =IFERROR(IF(M23="","",M23-20),M23) | W23: =ROW() -> 23
Q24: 10023 | V24: =IFERROR(IF(M24="","",M24-20),M24) | W24: =ROW() -> 24
A25: 小屋筋かい | D25: 13’×30×05 | E25: 杉 1ト | K25: 丁 | N25: × | O25: 現場 | Q25: 10024 | R25: 材 | S25: ﾀｶｶﾂ建材 ﾌﾟﾚｶｯﾄ | T25: 鈴木 | U25: TAKAKATSUP | V25: =IFERROR(IF(M25="","",M25-20),M25) | W25: =ROW() -> 25
A26: 外部下地 | C26: 外部の壁下地・入隅用 | D26: 13’×10×15 | E26: 杉 1ト | G26: 2F | H26: 42 | J26: 45 | K26: 丁 | L26: z | M26: 46167 | N26: ○ | O26: 現場 | Q26: 10025 | R26: 材 | S26: ﾀｶｶﾂ建材 ﾌﾟﾚｶｯﾄ | T26: 鈴木 | U26: TAKAKATSUP | V26: =IFERROR(IF(M26="","",M26-20),M26) -> 46147 | W26: =ROW() -> 26
A27: 外部下地 | C27: 外部の壁下地・入隅用 | D27: 13’×10×15 | E27: 杉 1ト | G27: 1F | H27: 43 | J27: 40 | K27: 丁 | L27: z | M27: 46167 | N27: ○ | O27: 現場 | Q27: 10026 | R27: 材 | S27: ﾀｶｶﾂ建材 ﾌﾟﾚｶｯﾄ | T27: 鈴木 | U27: TAKAKATSUP | V27: =IFERROR(IF(M27="","",M27-20),M27) -> 46147 | W27: =ROW() -> 27
Q28: 10027 | V28: =IFERROR(IF(M28="","",M28-20),M28) | W28: =ROW() -> 28
A29: ビルボード | C29: ﾔﾈｼﾀﾎﾞｰﾄﾞ | D29: t9 3’×6’ | K29: 枚 | N29: × | O29: 現場 | Q29: 10028 | R29: 外 | S29: O.S.S工業 | T29: 大槻 | U29: OSS | V29: =IFERROR(IF(M29="","",M29-20),M29) | W29: =ROW() -> 29
N30: ○ | Q30: 10029 | V30: =IFERROR(IF(M30="","",M30-20),M30) | W30: =ROW() -> 30
A31: リモコンコード | D31: UC-25-50A | E31: 2芯 50M | I31: 90m | J31: － | K31: 箱 | N31: ○ | O31: 事務所 | Q31: 10030 | R31: 材 | S31: 金辰商事 | T31: 内海 | U31: KANETATSU | V31: =IFERROR(IF(M31="","",M31-20),M31) | W31: =ROW() -> 31
A32: レベルプレート | D32: 1mm | H32: 1 | I32: 1 | J32: 1 | K32: 箱 | L32: z | M32: 46150 | N32: ○ | O32: 作業場 | Q32: 10031 | R32: 材 | S32: 三浦金物商会 | U32: MIURA | V32: =IFERROR(IF(M32="","",M32-20),M32) -> 46130 | W32: =ROW() -> 32
A33: レベルプレート | D33: 3mm | H33: 1 | I33: 1 | J33: － | K33: 箱 | N33: ○ | O33: 作業場 | Q33: 10032 | R33: 材 | S33: 三浦金物商会 | U33: MIURA | V33: =IFERROR(IF(M33="","",M33-20),M33) | W33: =ROW() -> 33
A34: ｽﾃﾝﾚｽ装飾柱受 | D34: SH-90角 | K34: 個 | N34: × | O34: 作業場 | Q34: 10033 | R34: 材 | S34: 三浦金物商会 | U34: MIURA | V34: =IFERROR(IF(M34="","",M34-20),M34) | W34: =ROW() -> 34
A35: オールアンカー | D35: M12 L90mm | E35: ｽﾃﾝﾚｽ | K35: 本 | N35: × | O35: 作業場 | Q35: 10034 | R35: 材 | S35: 三浦金物商会 | U35: MIURA | V35: =IFERROR(IF(M35="","",M35-20),M35) | W35: =ROW() -> 35
A36: オメガ丸座金70Ⅱ | H36: 5 | J36: 5 | K36: 個 | L36: z | M36: 46150 | N36: ○ | O36: 作業場 | Q36: 10035 | R36: 材 | S36: 三浦金物商会 | U36: MIURA | V36: =IFERROR(IF(M36="","",M36-20),M36) -> 46130 | W36: =ROW() -> 36
Q37: 10036 | V37: =IFERROR(IF(M37="","",M37-20),M37) | W37: =ROW() -> 37
A38: （鋼板屋根） | Q38: 10037 | V38: =IFERROR(IF(M38="","",M38-20),M38) | W38: =ROW() -> 38
A39: 破風・鼻隠し | D39: 13.2’×70×08 | E39: 杉 1ト | H39: 9 | J39: 9 | K39: 丁 | L39: z | M39: 46155 | N39: ○ | O39: 作業場 | Q39: 10038 | R39: 材 | S39: 渡辺製材所 | U39: WATANABE | V39: =IFERROR(IF(M39="","",M39-20),M39) -> 46135 | W39: =ROW() -> 39
A40: 破風・鼻隠し | C40: ポーチ屋根 | D40: 10’×60×08 | E40: 杉 1ト | K40: 丁 | N40: × | O40: 作業場 | Q40: 10039 | R40: 材 | S40: 渡辺製材所 | U40: WATANABE | V40: =IFERROR(IF(M40="","",M40-20),M40) | W40: =ROW() -> 40
...

Sheet 並べ替えビュー（納品内容）
A1: 名称 | B1: 規格 | C1: 規格 | D1: 規格 | E1: 階 | F1: 数量 | G1: 在庫 | H1: 発注 | I1: 単位 | J1: 納品日 | K1: 納品場所 | L1: 納品備考 | M1: 発注先 | N1: 元ｼｰﾄ行番号
A2: {=_xlfn.LET( _xlpm.元, _xlfn._xlws.FILTER( _xlfn.CHOOSECOLS(拾い出し!A2:X400, 1,4,5,6,7,8,9,10,11,13,15,16,19,23), 拾い出し!N2:N400="○" ), _xlpm.A列, IF(INDEX(_xlpm.元,,1)="","",INDEX(_xlpm.元,,1)), _xlpm.H列, IF(INDEX(_xlpm.元,,6)="","",INDEX(_xlpm.元,,6)), _xlpm.I列, IF(INDEX(_xlpm.元,,7)="","",INDEX(_xlpm.元,,7)), _xlpm.K列, IF(INDEX(_xlpm.元,,9)="","",INDEX(_xlpm.元,,9)), _xlpm.M列, IF(INDEX(_xlpm.元,,10)="","",INDEX(_xlpm.元,,10)), _xlfn.HSTACK( _xlpm.A列, INDEX(_xlpm.元,,2), INDEX(_xlpm.元,,3), INDEX(_xlpm.元,,4), INDEX(_xlpm.元,,5), _xlpm.H列, _xlpm.I列, INDEX(_xlpm.元,,8), _xlpm.K列, _xlpm.M列, INDEX(_xlpm.元,,11), INDEX(_xlpm.元,,12), INDEX(_xlpm.元,,13), INDEX(_xlpm.元,,14) ) )} -> スタイロフォーム | B2: t15 3’×6' | C2: 0 | D2: 基礎立上断熱 | E2: 0 | F2: 1+少 | H2: 1 | I2: 枚 | J2: 46122 | K2: 作業場 | L2: 0 | M2: 岡田電気産業 | N2: 5
A3: ミラフォーム | B3: t30 3’×6' | C3: 0 | D3: 基礎土間断熱 | E3: 0 | H3: 2 | I3: 枚 | J3: 46122 | K3: 作業場 | L3: 0 | M3: 岡田電気産業 | N3: 6
A4: ミラフォーム | B4: t30 3’×6' | C4: 0 | D4: 床下玄関立上り | E4: 0 | F4: 1 | H4: 3 | I4: 枚 | J4: 46122 | K4: 作業場 | L4: 0 | M4: 岡田電気産業 | N4: 7
A5: ミラフォーム | B5: t30 3’×6' | C5: 0 | D5: UB土間+立上り | E5: 0 | F5: 4 | H5: 4 | I5: 枚 | J5: 46122 | K5: 作業場 | L5: 0 | M5: 岡田電気産業 | N5: 8
A6: スタイロフォーム | B6: t15 3’×6’ | C6: 0 | D6: UB窓枠 | E6: 0 | F6: 1 | H6: 1 | I6: 枚 | J6: 46122 | K6: 作業場 | L6: 0 | M6: 岡田電気産業 | N6: 10
B7: 0 | C7: 0 | D7: 0 | E7: 0 | H7: 0 | K7: 0 | L7: 0 | M7: 0 | N7: 11
A8: プレカット材 | B8: 基礎ﾊﾟｯｷﾝ・床束 | C8: ・金物 | D8: 0 | E8: 0 | H8: 1 | I8: 式 | J8: 46167 | K8: 現場 | L8: 1便目：床組材・金物他 | M8: ﾀｶｶﾂ建材 ﾌﾟﾚｶｯﾄ | N8: 12
A9: ミラフォーム | B9: t50 3’×6’ | C9: 0 | D9: 0 | E9: 2F | F9: 5 | G9: 2 | H9: 5 | I9: 枚 | J9: 46167 | K9: 現場 | L9: 0 | M9: ﾀｶｶﾂ建材 ﾌﾟﾚｶｯﾄ | N9: 21
A10: ミラフォーム | B10: t65 3’×6’ | C10: 0 | D10: 0 | E10: 1F | H10: 0 | I10: 枚 | J10: 46167 | K10: 現場 | L10: 0 | M10: ﾀｶｶﾂ建材 ﾌﾟﾚｶｯﾄ | N10: 22
A11: 外部下地 | B11: 13’×10×15 | C11: 杉 1ト | D11: 0 | E11: 2F | F11: 42 | H11: 45 | I11: 丁 | J11: 46167 | K11: 現場 | L11: 0 | M11: ﾀｶｶﾂ建材 ﾌﾟﾚｶｯﾄ | N11: 26
A12: 外部下地 | B12: 13’×10×15 | C12: 杉 1ト | D12: 0 | E12: 1F | F12: 43 | H12: 40 | I12: 丁 | J12: 46167 | K12: 現場 | L12: 0 | M12: ﾀｶｶﾂ建材 ﾌﾟﾚｶｯﾄ | N12: 27
B13: 0 | C13: 0 | D13: 0 | E13: 0 | H13: 0 | K13: 0 | L13: 0 | M13: 0 | N13: 30
A14: リモコンコード | B14: UC-25-50A | C14: 2芯 50M | D14: 0 | E14: 0 | G14: 90m | H14: － | I14: 箱 | K14: 事務所 | L14: 0 | M14: 金辰商事 | N14: 31
A15: レベルプレート | B15: 1mm | C15: 0 | D15: 0 | E15: 0 | F15: 1 | G15: 1 | H15: 1 | I15: 箱 | J15: 46150 | K15: 作業場 | L15: 0 | M15: 三浦金物商会 | N15: 32
A16: レベルプレート | B16: 3mm | C16: 0 | D16: 0 | E16: 0 | F16: 1 | G16: 1 | H16: － | I16: 箱 | K16: 作業場 | L16: 0 | M16: 三浦金物商会 | N16: 33
A17: オメガ丸座金70Ⅱ | B17: 0 | C17: 0 | D17: 0 | E17: 0 | F17: 5 | H17: 5 | I17: 個 | J17: 46150 | K17: 作業場 | L17: 0 | M17: 三浦金物商会 | N17: 36
A18: 破風・鼻隠し | B18: 13.2’×70×08 | C18: 杉 1ト | D18: 0 | E18: 0 | F18: 9 | H18: 9 | I18: 丁 | J18: 46155 | K18: 作業場 | L18: 0 | M18: 渡辺製材所 | N18: 39
A19: 鼻隠し（水上側） | B19: 13.2’×72×08 | C19: 杉 1ト | D19: 0 | E19: 0 | F19: 3 | H19: 3 | I19: 丁 | J19: 46155 | K19: 作業場 | L19: 0 | M19: 渡辺製材所 | N19: 42
A20: 広小舞・登淀 | B20: 13.2’×30×05 | C20: 杉 1ト | D20: 0 | E20: 0 | F20: 12 | H20: 12 | I20: 丁 | J20: 46155 | K20: 作業場 | L20: 0 | M20: 渡辺製材所 | N20: 44
B21: 0 | C21: 0 | D21: 0 | E21: 0 | H21: 0 | K21: 0 | L21: 0 | M21: 0 | N21: 50
A22: サッシ LIXIL | B22: 0 | C22: 0 | D22: 0 | E22: 0 | F22: 1 | H22: 1 | I22: 式 | J22: 46177 | K22: 現場 | L22: 午前中（庇も） | M22: 岡田電気産業 | N22: 51
A23: 窓枠 LIXIL | B23: 0 | C23: 0 | D23: 0 | E23: 2F | F23: 1 | H23: 1 | I23: 式 | J23: 6月中旬 | K23: 現場 | L23: 0 | M23: 岡田電気産業 | N23: 52
A24: 窓枠 LIXIL | B24: 0 | C24: 0 | D24: 0 | E24: 1F | F24: 1 | H24: 1 | I24: 式 | J24: 6月中旬 | K24: 現場 | L24: 0 | M24: 岡田電気産業 | N24: 53
A25: 網戸 | B25: 0 | C25: 0 | D25: 0 | E25: 0 | F25: 1 | H25: 1 | I25: 式 | J25: 9月ごろ | K25: 現場 | L25: 0 | M25: 岡田電気産業 | N25: 54
A26: フェイスガード(逆巻) | B26: 1000mm×30M | C26: 4本/ｹｰｽ | D26: G02-001 | E26: 0 | F26: 2 | G26: 2 | H26: 2 | I26: ｹｰｽ | J26: 46142 | K26: 事務所 | L26: 0 | M26: 杉田エース | N26: 56
A27: 外部胴縁 | B27: 10’×15×05 | C27: 米松 1ト | D27: 0 | E27: 0 | F27: 156 | H27: 156 | I27: 丁 | J27: 46172 | K27: 現場 | L27: 午前中 | M27: 渡辺製材所 | N27: 60
A28: 外部胴縁 | B28: 10’×35×05 | C28: 米松 1ト | D28: 0 | E28: 0 | F28: 49 | H28: 50 | I28: 丁 | J28: 46172 | K28: 現場 | L28: 午前中 | M28: 渡辺製材所 | N28: 61
A29: ｼﾞｮｲﾝﾄ軒天下地 | B29: 12’×12×15 | C29: 杉 1ト | D29: 0 | E29: 0 | F29: 9 | G29: 16 | H29: － | I29: 丁 | K29: 現場 | L29: 午前中 | M29: 渡辺製材所 | N29: 62
A30: 野縁 軒天下地 | B30: 13’×12×13 | C30: 杉 1ト | D30: 9入/束 | E30: 0 | F30: 31本 | H30: 4 | I30: 束 | J30: 46172 | K30: 現場 | L30: 午前中 | M30: 渡辺製材所 | N30: 63
A31: 胴縁 | B31: 13’×12×08 | C31: 杉 1ト | D31: 12入/束 | E31: 2F | F31: 167本 | H31: 14 | I31: 束 | J31: 46170 | K31: 現場 | L31: 10：00までに(ｸﾚｰﾝ吊上) | M31: 渡辺製材所 | N31: 65
A32: 胴縁 | B32: 13’×12×08 | C32: 杉 1ト | D32: 12入/束 | E32: 1F | F32: 162本 | H32: 13 | I32: 束 | K32: 現場 | L32: 0 | M32: 渡辺製材所 | N32: 66
A33: 胴縁（追加） | B33: 13’×12×08 | C33: 杉 1ト | D33: 12入/束 | E33: 1F | H33: 0 | I33: 束 | K33: 現場 | L33: 0 | M33: 渡辺製材所 | N33: 67
A34: 野縁 | B34: 13’×12×13 | C34: 杉 1ト | D34: 9入/束 | E34: 2F | F34: 133本 | H34: 14 | I34: 束 | J34: 46170 | K34: 現場 | L34: 0 | M34: 渡辺製材所 | N34: 68
A35: 野縁 | B35: 13’×12×13 | C35: 杉 1ト | D35: 9入/束 | E35: 1F | F35: 101本 | H35: 11 | I35: 束 | K35: 現場 | L35: 0 | M35: 渡辺製材所 | N35: 69
A36: 野縁（追加） | B36: 13’×12×13 | C36: 杉 1ト | D36: 9入/束 | E36: 1F | H36: 0 | I36: 束 | K36: 現場 | L36: 0 | M36: 渡辺製材所 | N36: 70
A37: 防虫網 | B37: BSF-1518 | C37: 20本/ｹｰｽ | D37: 0 | E37: 0 | F37: 21本 | G37: 8本 | H37: 2 | I37: ｹｰｽ | J37: 46132 | K37: 5/11～15 | L37: までに作業場 | M37: タカカツ建材 | N37: 75
A38: 高気密型天井点検口 | B38: SPC-4545B(1) | C38: Joto | D38: 0 | E38: 0 | F38: 1 | H38: 1 | I38: 台 | J38: 46132 | K38: 5/11～15 | L38: までに作業場 | M38: タカカツ建材 | N38: 76
A39: 防振吊木 MAX399㎜ | B39: TH-10(在来) | C39: (20本×2) | D39: 40本/ｹｰｽ | E39: 0 | F39: 1 | G39: 1 | H39: 1 | I39: ｹｰｽ | J39: 46132 | K39: 5/11～15 | L39: までに作業場 | M39: タカカツ建材 | N39: 77
A40: 防振吊木 MAX217㎜ | B40: TH-30(枠組) | C40: (20本×2) | D40: 40本/ｹｰｽ | E40: 0 | F40: 1 | G40: 1 | H40: 1 | I40: ｹｰｽ | J40: 46132 | K40: 5/11～15 | L40: までに作業場 | M40: タカカツ建材 | N40: 78
...

Sheet 発注書
A1: 材料コード | B1: 発注日 | E1: 発注業者 | F1: 担当者 | G1: 名称 | H1: 規格 | I1: 規格 | J1: 規格 | K1: 階 | L1: 発注 | M1: 単位 | N1: 納品日 | O1: 納品場所 | P1: 納品備考
A2: 10293 | B2: =TODAY() -> 46168 | E2: =IF(A2="","",_xlfn.XLOOKUP(A2,拾い出し!Q:Q,拾い出し!S:S,"")) -> 岡田電気産業 | F2: =IF(A2="","",_xlfn.XLOOKUP(A2,拾い出し!Q:Q,拾い出し!T:T,"")) -> 大槻 | G2: =IF(A2="","",_xlfn.XLOOKUP(A2,拾い出し!Q:Q,拾い出し!A:A,"")) -> ﾊﾟｲﾌﾟ用ﾌｧﾝ 24H換気 | H2: =IF(A2="","",_xlfn.XLOOKUP(A2,拾い出し!Q:Q,拾い出し!D:D,"")) -> V-08PLD8 φ100㎜ | I2: =IF(A2="","",_xlfn.XLOOKUP(A2,拾い出し!Q:Q,拾い出し!E:E,"")) -> 1階 洗濯室 | J2: =IF(A2="","",_xlfn.XLOOKUP(A2,拾い出し!Q:Q,拾い出し!F:F,"")) -> 連結端子接続 | K2: =IF(A2="","",_xlfn.XLOOKUP(A2,拾い出し!Q:Q,拾い出し!G:G,"")) -> 0 | L2: =IF(A2="","",_xlfn.XLOOKUP(A2,拾い出し!Q:Q,拾い出し!J:J,"")) -> 1 | M2: =IF(A2="","",_xlfn.XLOOKUP(A2,拾い出し!Q:Q,拾い出し!K:K,"")) -> 台 | N2: =IF(A2="","",_xlfn.XLOOKUP(A2,拾い出し!Q:Q,拾い出し!M:M,"")) -> 0 | O2: =IF(A2="","",_xlfn.XLOOKUP(A2,拾い出し!Q:Q,拾い出し!O:O,"")) -> 事務所 | P2: =IF(A2="","",_xlfn.XLOOKUP(A2,拾い出し!Q:Q,拾い出し!P:P,"")) -> 0
A3: 10294 | E3: =IF(A3="","",_xlfn.XLOOKUP(A3,拾い出し!Q:Q,拾い出し!S:S,"")) -> 岡田電気産業 | F3: =IF(A3="","",_xlfn.XLOOKUP(A3,拾い出し!Q:Q,拾い出し!T:T,"")) -> 大槻 | G3: =IF(A3="","",_xlfn.XLOOKUP(A3,拾い出し!Q:Q,拾い出し!A:A,"")) -> ほこり取りﾌｨﾙﾀｰ | H3: =IF(A3="","",_xlfn.XLOOKUP(A3,拾い出し!Q:Q,拾い出し!D:D,"")) -> P-08PNET | I3: =IF(A3="","",_xlfn.XLOOKUP(A3,拾い出し!Q:Q,拾い出し!E:E,"")) -> 0 | J3: =IF(A3="","",_xlfn.XLOOKUP(A3,拾い出し!Q:Q,拾い出し!F:F,"")) -> 0 | K3: =IF(A3="","",_xlfn.XLOOKUP(A3,拾い出し!Q:Q,拾い出し!G:G,"")) -> 0 | L3: =IF(A3="","",_xlfn.XLOOKUP(A3,拾い出し!Q:Q,拾い出し!J:J,"")) -> 1 | M3: =IF(A3="","",_xlfn.XLOOKUP(A3,拾い出し!Q:Q,拾い出し!K:K,"")) -> 枚 | N3: =IF(A3="","",_xlfn.XLOOKUP(A3,拾い出し!Q:Q,拾い出し!M:M,"")) -> 0 | O3: =IF(A3="","",_xlfn.XLOOKUP(A3,拾い出し!Q:Q,拾い出し!O:O,"")) -> 0 | P3: =IF(A3="","",_xlfn.XLOOKUP(A3,拾い出し!Q:Q,拾い出し!P:P,"")) -> 0
A4: 10295 | E4: =IF(A4="","",_xlfn.XLOOKUP(A4,拾い出し!Q:Q,拾い出し!S:S,"")) -> 岡田電気産業 | F4: =IF(A4="","",_xlfn.XLOOKUP(A4,拾い出し!Q:Q,拾い出し!T:T,"")) -> 大槻 | G4: =IF(A4="","",_xlfn.XLOOKUP(A4,拾い出し!Q:Q,拾い出し!A:A,"")) -> ﾊﾟｲﾌﾟ用ﾌｧﾝ | H4: =IF(A4="","",_xlfn.XLOOKUP(A4,拾い出し!Q:Q,拾い出し!D:D,"")) -> V-08PSD8 φ100㎜ | I4: =IF(A4="","",_xlfn.XLOOKUP(A4,拾い出し!Q:Q,拾い出し!E:E,"")) -> 1階 応接室 | J4: =IF(A4="","",_xlfn.XLOOKUP(A4,拾い出し!Q:Q,拾い出し!F:F,"")) -> 電気式ｼｬｯﾀｰ付 | K4: =IF(A4="","",_xlfn.XLOOKUP(A4,拾い出し!Q:Q,拾い出し!G:G,"")) -> 0 | L4: =IF(A4="","",_xlfn.XLOOKUP(A4,拾い出し!Q:Q,拾い出し!J:J,"")) -> 1 | M4: =IF(A4="","",_xlfn.XLOOKUP(A4,拾い出し!Q:Q,拾い出し!K:K,"")) -> 台 | N4: =IF(A4="","",_xlfn.XLOOKUP(A4,拾い出し!Q:Q,拾い出し!M:M,"")) -> 0 | O4: =IF(A4="","",_xlfn.XLOOKUP(A4,拾い出し!Q:Q,拾い出し!O:O,"")) -> 0 | P4: =IF(A4="","",_xlfn.XLOOKUP(A4,拾い出し!Q:Q,拾い出し!P:P,"")) -> 0
A5: 10296 | E5: =IF(A5="","",_xlfn.XLOOKUP(A5,拾い出し!Q:Q,拾い出し!S:S,"")) -> 岡田電気産業 | F5: =IF(A5="","",_xlfn.XLOOKUP(A5,拾い出し!Q:Q,拾い出し!T:T,"")) -> 大槻 | G5: =IF(A5="","",_xlfn.XLOOKUP(A5,拾い出し!Q:Q,拾い出し!A:A,"")) -> ﾊﾟｲﾌﾟ用ﾌｧﾝ | H5: =IF(A5="","",_xlfn.XLOOKUP(A5,拾い出し!Q:Q,拾い出し!D:D,"")) -> V-08PASD8 φ100㎜ | I5: =IF(A5="","",_xlfn.XLOOKUP(A5,拾い出し!Q:Q,拾い出し!E:E,"")) -> 1階/2階ﾄｲﾚ | J5: =IF(A5="","",_xlfn.XLOOKUP(A5,拾い出し!Q:Q,拾い出し!F:F,"")) -> 人感ｾﾝｻ/電気式ｼｬｯﾀｰ | K5: =IF(A5="","",_xlfn.XLOOKUP(A5,拾い出し!Q:Q,拾い出し!G:G,"")) -> 0 | L5: =IF(A5="","",_xlfn.XLOOKUP(A5,拾い出し!Q:Q,拾い出し!J:J,"")) -> 2 | M5: =IF(A5="","",_xlfn.XLOOKUP(A5,拾い出し!Q:Q,拾い出し!K:K,"")) -> 台 | N5: =IF(A5="","",_xlfn.XLOOKUP(A5,拾い出し!Q:Q,拾い出し!M:M,"")) -> 0 | O5: =IF(A5="","",_xlfn.XLOOKUP(A5,拾い出し!Q:Q,拾い出し!O:O,"")) -> 0 | P5: =IF(A5="","",_xlfn.XLOOKUP(A5,拾い出し!Q:Q,拾い出し!P:P,"")) -> 0
A6: 10297 | E6: =IF(A6="","",_xlfn.XLOOKUP(A6,拾い出し!Q:Q,拾い出し!S:S,"")) -> 岡田電気産業 | F6: =IF(A6="","",_xlfn.XLOOKUP(A6,拾い出し!Q:Q,拾い出し!T:T,"")) -> 大槻 | G6: =IF(A6="","",_xlfn.XLOOKUP(A6,拾い出し!Q:Q,拾い出し!A:A,"")) -> ﾀﾞｸﾄ用換気扇 24H換気 | H6: =IF(A6="","",_xlfn.XLOOKUP(A6,拾い出し!Q:Q,拾い出し!D:D,"")) -> VD-13ZLC14-S | I6: =IF(A6="","",_xlfn.XLOOKUP(A6,拾い出し!Q:Q,拾い出し!E:E,"")) -> 1階 事務室 | J6: =IF(A6="","",_xlfn.XLOOKUP(A6,拾い出し!Q:Q,拾い出し!F:F,"")) -> φ100㎜天井埋込形 | K6: =IF(A6="","",_xlfn.XLOOKUP(A6,拾い出し!Q:Q,拾い出し!G:G,"")) -> 0 | L6: =IF(A6="","",_xlfn.XLOOKUP(A6,拾い出し!Q:Q,拾い出し!J:J,"")) -> 1 | M6: =IF(A6="","",_xlfn.XLOOKUP(A6,拾い出し!Q:Q,拾い出し!K:K,"")) -> 台 | N6: =IF(A6="","",_xlfn.XLOOKUP(A6,拾い出し!Q:Q,拾い出し!M:M,"")) -> 0 | O6: =IF(A6="","",_xlfn.XLOOKUP(A6,拾い出し!Q:Q,拾い出し!O:O,"")) -> 0 | P6: =IF(A6="","",_xlfn.XLOOKUP(A6,拾い出し!Q:Q,拾い出し!P:P,"")) -> 0
A7: 10298 | E7: =IF(A7="","",_xlfn.XLOOKUP(A7,拾い出し!Q:Q,拾い出し!S:S,"")) -> 岡田電気産業 | F7: =IF(A7="","",_xlfn.XLOOKUP(A7,拾い出し!Q:Q,拾い出し!T:T,"")) -> 大槻 | G7: =IF(A7="","",_xlfn.XLOOKUP(A7,拾い出し!Q:Q,拾い出し!A:A,"")) -> ﾀﾞｸﾄ用換気扇 24H換気 | H7: =IF(A7="","",_xlfn.XLOOKUP(A7,拾い出し!Q:Q,拾い出し!D:D,"")) -> VD-18ZLSC14-S | I7: =IF(A7="","",_xlfn.XLOOKUP(A7,拾い出し!Q:Q,拾い出し!E:E,"")) -> 2階 廊下 | J7: =IF(A7="","",_xlfn.XLOOKUP(A7,拾い出し!Q:Q,拾い出し!F:F,"")) -> φ100㎜天井埋込形 | K7: =IF(A7="","",_xlfn.XLOOKUP(A7,拾い出し!Q:Q,拾い出し!G:G,"")) -> 0 | L7: =IF(A7="","",_xlfn.XLOOKUP(A7,拾い出し!Q:Q,拾い出し!J:J,"")) -> 1 | M7: =IF(A7="","",_xlfn.XLOOKUP(A7,拾い出し!Q:Q,拾い出し!K:K,"")) -> 台 | N7: =IF(A7="","",_xlfn.XLOOKUP(A7,拾い出し!Q:Q,拾い出し!M:M,"")) -> 0 | O7: =IF(A7="","",_xlfn.XLOOKUP(A7,拾い出し!Q:Q,拾い出し!O:O,"")) -> 0 | P7: =IF(A7="","",_xlfn.XLOOKUP(A7,拾い出し!Q:Q,拾い出し!P:P,"")) -> 0
A8: 10299 | E8: =IF(A8="","",_xlfn.XLOOKUP(A8,拾い出し!Q:Q,拾い出し!S:S,"")) -> 岡田電気産業 | F8: =IF(A8="","",_xlfn.XLOOKUP(A8,拾い出し!Q:Q,拾い出し!T:T,"")) -> 大槻 | G8: =IF(A8="","",_xlfn.XLOOKUP(A8,拾い出し!Q:Q,拾い出し!A:A,"")) -> ﾀﾞｸﾄ用換気扇 | H8: =IF(A8="","",_xlfn.XLOOKUP(A8,拾い出し!Q:Q,拾い出し!D:D,"")) -> VD-18ZX14-C | I8: =IF(A8="","",_xlfn.XLOOKUP(A8,拾い出し!Q:Q,拾い出し!E:E,"")) -> 2階 廊下 | J8: =IF(A8="","",_xlfn.XLOOKUP(A8,拾い出し!Q:Q,拾い出し!F:F,"")) -> φ150㎜天井埋込形 | K8: =IF(A8="","",_xlfn.XLOOKUP(A8,拾い出し!Q:Q,拾い出し!G:G,"")) -> 0 | L8: =IF(A8="","",_xlfn.XLOOKUP(A8,拾い出し!Q:Q,拾い出し!J:J,"")) -> 1 | M8: =IF(A8="","",_xlfn.XLOOKUP(A8,拾い出し!Q:Q,拾い出し!K:K,"")) -> 台 | N8: =IF(A8="","",_xlfn.XLOOKUP(A8,拾い出し!Q:Q,拾い出し!M:M,"")) -> 0 | O8: =IF(A8="","",_xlfn.XLOOKUP(A8,拾い出し!Q:Q,拾い出し!O:O,"")) -> 0 | P8: =IF(A8="","",_xlfn.XLOOKUP(A8,拾い出し!Q:Q,拾い出し!P:P,"")) -> 0
E9: =IF(A9="","",_xlfn.XLOOKUP(A9,拾い出し!Q:Q,拾い出し!S:S,"")) | F9: =IF(A9="","",_xlfn.XLOOKUP(A9,拾い出し!Q:Q,拾い出し!T:T,"")) | G9: =IF(A9="","",_xlfn.XLOOKUP(A9,拾い出し!Q:Q,拾い出し!A:A,"")) | H9: =IF(A9="","",_xlfn.XLOOKUP(A9,拾い出し!Q:Q,拾い出し!D:D,"")) | I9: =IF(A9="","",_xlfn.XLOOKUP(A9,拾い出し!Q:Q,拾い出し!E:E,"")) | J9: =IF(A9="","",_xlfn.XLOOKUP(A9,拾い出し!Q:Q,拾い出し!F:F,"")) | K9: =IF(A9="","",_xlfn.XLOOKUP(A9,拾い出し!Q:Q,拾い出し!G:G,"")) | L9: =IF(A9="","",_xlfn.XLOOKUP(A9,拾い出し!Q:Q,拾い出し!J:J,"")) | M9: =IF(A9="","",_xlfn.XLOOKUP(A9,拾い出し!Q:Q,拾い出し!K:K,"")) | N9: =IF(A9="","",_xlfn.XLOOKUP(A9,拾い出し!Q:Q,拾い出し!M:M,"")) | O9: =IF(A9="","",_xlfn.XLOOKUP(A9,拾い出し!Q:Q,拾い出し!O:O,"")) | P9: =IF(A9="","",_xlfn.XLOOKUP(A9,拾い出し!Q:Q,拾い出し!P:P,""))
E10: =IF(A10="","",_xlfn.XLOOKUP(A10,拾い出し!Q:Q,拾い出し!S:S,"")) | F10: =IF(A10="","",_xlfn.XLOOKUP(A10,拾い出し!Q:Q,拾い出し!T:T,"")) | G10: =IF(A10="","",_xlfn.XLOOKUP(A10,拾い出し!Q:Q,拾い出し!A:A,"")) | H10: =IF(A10="","",_xlfn.XLOOKUP(A10,拾い出し!Q:Q,拾い出し!D:D,"")) | I10: =IF(A10="","",_xlfn.XLOOKUP(A10,拾い出し!Q:Q,拾い出し!E:E,"")) | J10: =IF(A10="","",_xlfn.XLOOKUP(A10,拾い出し!Q:Q,拾い出し!F:F,"")) | K10: =IF(A10="","",_xlfn.XLOOKUP(A10,拾い出し!Q:Q,拾い出し!G:G,"")) | L10: =IF(A10="","",_xlfn.XLOOKUP(A10,拾い出し!Q:Q,拾い出し!J:J,"")) | M10: =IF(A10="","",_xlfn.XLOOKUP(A10,拾い出し!Q:Q,拾い出し!K:K,"")) | N10: =IF(A10="","",_xlfn.XLOOKUP(A10,拾い出し!Q:Q,拾い出し!M:M,"")) | O10: =IF(A10="","",_xlfn.XLOOKUP(A10,拾い出し!Q:Q,拾い出し!O:O,"")) | P10: =IF(A10="","",_xlfn.XLOOKUP(A10,拾い出し!Q:Q,拾い出し!P:P,""))
E11: =IF(A11="","",_xlfn.XLOOKUP(A11,拾い出し!Q:Q,拾い出し!S:S,"")) | F11: =IF(A11="","",_xlfn.XLOOKUP(A11,拾い出し!Q:Q,拾い出し!T:T,"")) | G11: =IF(A11="","",_xlfn.XLOOKUP(A11,拾い出し!Q:Q,拾い出し!A:A,"")) | H11: =IF(A11="","",_xlfn.XLOOKUP(A11,拾い出し!Q:Q,拾い出し!D:D,"")) | I11: =IF(A11="","",_xlfn.XLOOKUP(A11,拾い出し!Q:Q,拾い出し!E:E,"")) | J11: =IF(A11="","",_xlfn.XLOOKUP(A11,拾い出し!Q:Q,拾い出し!F:F,"")) | K11: =IF(A11="","",_xlfn.XLOOKUP(A11,拾い出し!Q:Q,拾い出し!G:G,"")) | L11: =IF(A11="","",_xlfn.XLOOKUP(A11,拾い出し!Q:Q,拾い出し!J:J,"")) | M11: =IF(A11="","",_xlfn.XLOOKUP(A11,拾い出し!Q:Q,拾い出し!K:K,"")) | N11: =IF(A11="","",_xlfn.XLOOKUP(A11,拾い出し!Q:Q,拾い出し!M:M,"")) | O11: =IF(A11="","",_xlfn.XLOOKUP(A11,拾い出し!Q:Q,拾い出し!O:O,"")) | P11: =IF(A11="","",_xlfn.XLOOKUP(A11,拾い出し!Q:Q,拾い出し!P:P,""))
E12: =IF(A12="","",_xlfn.XLOOKUP(A12,拾い出し!Q:Q,拾い出し!S:S,"")) | F12: =IF(A12="","",_xlfn.XLOOKUP(A12,拾い出し!Q:Q,拾い出し!T:T,"")) | G12: =IF(A12="","",_xlfn.XLOOKUP(A12,拾い出し!Q:Q,拾い出し!A:A,"")) | H12: =IF(A12="","",_xlfn.XLOOKUP(A12,拾い出し!Q:Q,拾い出し!D:D,"")) | I12: =IF(A12="","",_xlfn.XLOOKUP(A12,拾い出し!Q:Q,拾い出し!E:E,"")) | J12: =IF(A12="","",_xlfn.XLOOKUP(A12,拾い出し!Q:Q,拾い出し!F:F,"")) | K12: =IF(A12="","",_xlfn.XLOOKUP(A12,拾い出し!Q:Q,拾い出し!G:G,"")) | L12: =IF(A12="","",_xlfn.XLOOKUP(A12,拾い出し!Q:Q,拾い出し!J:J,"")) | M12: =IF(A12="","",_xlfn.XLOOKUP(A12,拾い出し!Q:Q,拾い出し!K:K,"")) | N12: =IF(A12="","",_xlfn.XLOOKUP(A12,拾い出し!Q:Q,拾い出し!M:M,"")) | O12: =IF(A12="","",_xlfn.XLOOKUP(A12,拾い出し!Q:Q,拾い出し!O:O,"")) | P12: =IF(A12="","",_xlfn.XLOOKUP(A12,拾い出し!Q:Q,拾い出し!P:P,""))
E13: =IF(A13="","",_xlfn.XLOOKUP(A13,拾い出し!Q:Q,拾い出し!S:S,"")) | F13: =IF(A13="","",_xlfn.XLOOKUP(A13,拾い出し!Q:Q,拾い出し!T:T,"")) | G13: =IF(A13="","",_xlfn.XLOOKUP(A13,拾い出し!Q:Q,拾い出し!A:A,"")) | H13: =IF(A13="","",_xlfn.XLOOKUP(A13,拾い出し!Q:Q,拾い出し!D:D,"")) | I13: =IF(A13="","",_xlfn.XLOOKUP(A13,拾い出し!Q:Q,拾い出し!E:E,"")) | J13: =IF(A13="","",_xlfn.XLOOKUP(A13,拾い出し!Q:Q,拾い出し!F:F,"")) | K13: =IF(A13="","",_xlfn.XLOOKUP(A13,拾い出し!Q:Q,拾い出し!G:G,"")) | L13: =IF(A13="","",_xlfn.XLOOKUP(A13,拾い出し!Q:Q,拾い出し!J:J,"")) | M13: =IF(A13="","",_xlfn.XLOOKUP(A13,拾い出し!Q:Q,拾い出し!K:K,"")) | N13: =IF(A13="","",_xlfn.XLOOKUP(A13,拾い出し!Q:Q,拾い出し!M:M,"")) | O13: =IF(A13="","",_xlfn.XLOOKUP(A13,拾い出し!Q:Q,拾い出し!O:O,"")) | P13: =IF(A13="","",_xlfn.XLOOKUP(A13,拾い出し!Q:Q,拾い出し!P:P,""))
E14: =IF(A14="","",_xlfn.XLOOKUP(A14,拾い出し!Q:Q,拾い出し!S:S,"")) | F14: =IF(A14="","",_xlfn.XLOOKUP(A14,拾い出し!Q:Q,拾い出し!T:T,"")) | G14: =IF(A14="","",_xlfn.XLOOKUP(A14,拾い出し!Q:Q,拾い出し!A:A,"")) | H14: =IF(A14="","",_xlfn.XLOOKUP(A14,拾い出し!Q:Q,拾い出し!D:D,"")) | I14: =IF(A14="","",_xlfn.XLOOKUP(A14,拾い出し!Q:Q,拾い出し!E:E,"")) | J14: =IF(A14="","",_xlfn.XLOOKUP(A14,拾い出し!Q:Q,拾い出し!F:F,"")) | K14: =IF(A14="","",_xlfn.XLOOKUP(A14,拾い出し!Q:Q,拾い出し!G:G,"")) | L14: =IF(A14="","",_xlfn.XLOOKUP(A14,拾い出し!Q:Q,拾い出し!J:J,"")) | M14: =IF(A14="","",_xlfn.XLOOKUP(A14,拾い出し!Q:Q,拾い出し!K:K,"")) | N14: =IF(A14="","",_xlfn.XLOOKUP(A14,拾い出し!Q:Q,拾い出し!M:M,"")) | O14: =IF(A14="","",_xlfn.XLOOKUP(A14,拾い出し!Q:Q,拾い出し!O:O,"")) | P14: =IF(A14="","",_xlfn.XLOOKUP(A14,拾い出し!Q:Q,拾い出し!P:P,""))
E15: =IF(A15="","",_xlfn.XLOOKUP(A15,拾い出し!Q:Q,拾い出し!S:S,"")) | F15: =IF(A15="","",_xlfn.XLOOKUP(A15,拾い出し!Q:Q,拾い出し!T:T,"")) | G15: =IF(A15="","",_xlfn.XLOOKUP(A15,拾い出し!Q:Q,拾い出し!A:A,"")) | H15: =IF(A15="","",_xlfn.XLOOKUP(A15,拾い出し!Q:Q,拾い出し!D:D,"")) | I15: =IF(A15="","",_xlfn.XLOOKUP(A15,拾い出し!Q:Q,拾い出し!E:E,"")) | J15: =IF(A15="","",_xlfn.XLOOKUP(A15,拾い出し!Q:Q,拾い出し!F:F,"")) | K15: =IF(A15="","",_xlfn.XLOOKUP(A15,拾い出し!Q:Q,拾い出し!G:G,"")) | L15: =IF(A15="","",_xlfn.XLOOKUP(A15,拾い出し!Q:Q,拾い出し!J:J,"")) | M15: =IF(A15="","",_xlfn.XLOOKUP(A15,拾い出し!Q:Q,拾い出し!K:K,"")) | N15: =IF(A15="","",_xlfn.XLOOKUP(A15,拾い出し!Q:Q,拾い出し!M:M,"")) | O15: =IF(A15="","",_xlfn.XLOOKUP(A15,拾い出し!Q:Q,拾い出し!O:O,"")) | P15: =IF(A15="","",_xlfn.XLOOKUP(A15,拾い出し!Q:Q,拾い出し!P:P,""))

Sheet 連絡書
A1: 連絡書 | C1: Date | D1: =発注書!B2 -> 46168 | E1: No. | F1: 1 | G1: / | H1: 1
A2: =発注書!E2 -> 岡田電気産業 | C2: =IF(発注書!F2=0,"",発注書!F2) -> 大槻 | D2: 様
A3: 件名 | B3: 白石送電事務所 | C3: 新築工事
A5: □ | B5: =IF(発注書!G2=0,"",発注書!G2) -> ﾊﾟｲﾌﾟ用ﾌｧﾝ 24H換気 | C5: =IF(発注書!H2=0,"",発注書!H2) -> V-08PLD8 φ100㎜ | D5: =IF(発注書!I2=0,"",発注書!I2) -> 1階 洗濯室 | E5: =IF(発注書!J2=0,"",発注書!J2) -> 連結端子接続 | F5: =IF(発注書!L2=0,"",発注書!L2) -> 1 | G5: =IF(発注書!M2=0,"",発注書!M2) -> 台 | H5: =IF(発注書!K2=0,"",発注書!K2)
A6: □ | B6: =IF(発注書!G3=0,"",発注書!G3) -> ほこり取りﾌｨﾙﾀｰ | C6: =IF(発注書!H3=0,"",発注書!H3) -> P-08PNET | D6: =IF(発注書!I3=0,"",発注書!I3) | E6: =IF(発注書!J3=0,"",発注書!J3) | F6: =IF(発注書!L3=0,"",発注書!L3) -> 1 | G6: =IF(発注書!M3=0,"",発注書!M3) -> 枚 | H6: =IF(発注書!K3=0,"",発注書!K3)
A7: □ | B7: =IF(発注書!G4=0,"",発注書!G4) -> ﾊﾟｲﾌﾟ用ﾌｧﾝ | C7: =IF(発注書!H4=0,"",発注書!H4) -> V-08PSD8 φ100㎜ | D7: =IF(発注書!I4=0,"",発注書!I4) -> 1階 応接室 | E7: =IF(発注書!J4=0,"",発注書!J4) -> 電気式ｼｬｯﾀｰ付 | F7: =IF(発注書!L4=0,"",発注書!L4) -> 1 | G7: =IF(発注書!M4=0,"",発注書!M4) -> 台 | H7: =IF(発注書!K4=0,"",発注書!K4)
A8: □ | B8: =IF(発注書!G5=0,"",発注書!G5) -> ﾊﾟｲﾌﾟ用ﾌｧﾝ | C8: =IF(発注書!H5=0,"",発注書!H5) -> V-08PASD8 φ100㎜ | D8: =IF(発注書!I5=0,"",発注書!I5) -> 1階/2階ﾄｲﾚ | E8: =IF(発注書!J5=0,"",発注書!J5) -> 人感ｾﾝｻ/電気式ｼｬｯﾀｰ | F8: =IF(発注書!L5=0,"",発注書!L5) -> 2 | G8: =IF(発注書!M5=0,"",発注書!M5) -> 台 | H8: =IF(発注書!K5=0,"",発注書!K5)
A9: □ | B9: =IF(発注書!G6=0,"",発注書!G6) -> ﾀﾞｸﾄ用換気扇 24H換気 | C9: =IF(発注書!H6=0,"",発注書!H6) -> VD-13ZLC14-S | D9: =IF(発注書!I6=0,"",発注書!I6) -> 1階 事務室 | E9: =IF(発注書!J6=0,"",発注書!J6) -> φ100㎜天井埋込形 | F9: =IF(発注書!L6=0,"",発注書!L6) -> 1 | G9: =IF(発注書!M6=0,"",発注書!M6) -> 台 | H9: =IF(発注書!K6=0,"",発注書!K6)
A10: □ | B10: =IF(発注書!G7=0,"",発注書!G7) -> ﾀﾞｸﾄ用換気扇 24H換気 | C10: =IF(発注書!H7=0,"",発注書!H7) -> VD-18ZLSC14-S | D10: =IF(発注書!I7=0,"",発注書!I7) -> 2階 廊下 | E10: =IF(発注書!J7=0,"",発注書!J7) -> φ100㎜天井埋込形 | F10: =IF(発注書!L7=0,"",発注書!L7) -> 1 | G10: =IF(発注書!M7=0,"",発注書!M7) -> 台 | H10: =IF(発注書!K7=0,"",発注書!K7)
A11: □ | B11: =IF(発注書!G8=0,"",発注書!G8) -> ﾀﾞｸﾄ用換気扇 | C11: =IF(発注書!H8=0,"",発注書!H8) -> VD-18ZX14-C | D11: =IF(発注書!I8=0,"",発注書!I8) -> 2階 廊下 | E11: =IF(発注書!J8=0,"",発注書!J8) -> φ150㎜天井埋込形 | F11: =IF(発注書!L8=0,"",発注書!L8) -> 1 | G11: =IF(発注書!M8=0,"",発注書!M8) -> 台 | H11: =IF(発注書!K8=0,"",発注書!K8)
A12: □ | B12: =IF(発注書!G9=0,"",発注書!G9) | C12: =IF(発注書!H9=0,"",発注書!H9) | D12: =IF(発注書!I9=0,"",発注書!I9) | E12: =IF(発注書!J9=0,"",発注書!J9) | F12: =IF(発注書!L9=0,"",発注書!L9) | G12: =IF(発注書!M9=0,"",発注書!M9) | H12: =IF(発注書!K9=0,"",発注書!K9)
A13: □ | B13: =IF(発注書!G10=0,"",発注書!G10) | C13: =IF(発注書!H10=0,"",発注書!H10) | D13: =IF(発注書!I10=0,"",発注書!I10) | E13: =IF(発注書!J10=0,"",発注書!J10) | F13: =IF(発注書!L10=0,"",発注書!L10) | G13: =IF(発注書!M10=0,"",発注書!M10) | H13: =IF(発注書!K10=0,"",発注書!K10)
A14: □ | B14: =IF(発注書!G11=0,"",発注書!G11) | C14: =IF(発注書!H11=0,"",発注書!H11) | D14: =IF(発注書!I11=0,"",発注書!I11) | E14: =IF(発注書!J11=0,"",発注書!J11) | F14: =IF(発注書!L11=0,"",発注書!L11) | G14: =IF(発注書!M11=0,"",発注書!M11) | H14: =IF(発注書!K11=0,"",発注書!K11)
A15: □ | B15: =IF(発注書!G12=0,"",発注書!G12) | C15: =IF(発注書!H12=0,"",発注書!H12) | D15: =IF(発注書!I12=0,"",発注書!I12) | E15: =IF(発注書!J12=0,"",発注書!J12) | F15: =IF(発注書!L12=0,"",発注書!L12) | G15: =IF(発注書!M12=0,"",発注書!M12) | H15: =IF(発注書!K12=0,"",発注書!K12)
A16: □ | B16: =IF(発注書!G13=0,"",発注書!G13) | C16: =IF(発注書!H13=0,"",発注書!H13) | D16: =IF(発注書!I13=0,"",発注書!I13) | E16: =IF(発注書!J13=0,"",発注書!J13) | F16: =IF(発注書!L13=0,"",発注書!L13) | G16: =IF(発注書!M13=0,"",発注書!M13) | H16: =IF(発注書!K13=0,"",発注書!K13)
... A18: □ | B18: =IF(発注書!G15=0,"",発注書!G15) | C18: =IF(発注書!H15=0,"",発注書!H15) | D18: =IF(発注書!I15=0,"",発注書!I15) | E18: =IF(発注書!J15=0,"",発注書!J15) | F18: =IF(発注書!L15=0,"",発注書!L15) | G18: =IF(発注書!M15=0,"",発注書!M15) | H18: =IF(発注書!K15=0,"",発注書!K15)
B19: ※上記 | C19: =IF(発注書!N2=0,"",発注書!N2) | D19: =IF(発注書!O2=0,"",発注書!O2) -> 事務所 | E19: =IF(発注書!P2=0,"",発注書!P2)
E20: 納品お願いします

Sheet ﾃｷｽﾄﾎﾞｯｸｽ

Sheet 外壁貼り手間
A2: 連絡書
E3: Date | F3: 2026 | G3: ・ | H3: 5 | I3: ・ | J3: 27 | K3: No. | L3: 1 | M3: / | N3: 1
A6: 大橋サイディング
A8: 件名 | B8: 白石送電事務所 新築工事
A11: 外壁工事について
A13: 貼り手間 | C13: 2階建て | F13: 217 | G13: × | J13: /㎡ | K13: = | L13: =F13*H13 -> 0
L14: (消費税別）
A15: 施工期間
C17: 46189 | F17: ～ | G17: 46198
A19: 外壁不足分貼り | F19: ～ | G19: 46204
A23: （ｼｰﾘﾝｸﾞ工事予定 | E23: 46205 | H23: ～ | I23: 46213 | M23: ）
C25: 上記のとおり工事予定お願いします

Sheet シーリング工
A2: 連絡書
E3: Date | F3: 2026 | G3: ・ | H3: 5 | I3: ・ | J3: 11 | K3: No. | L3: 1 | M3: / | N3: 1
A6: 佐藤シール
A8: 件名 | B8: 白石送電事務所 新築工事
A11: シーリング工事について
A13: 【本体】
A14: ニチハ | D14: モエンエクセラード16 | G14: Vｼﾘｰｽﾞ | J14: 金具止め
A15: キアンカV | E15: EFA5653 | G15: ｱｲﾘｵMGﾌﾞﾗｳﾝ
A16: 長尺出隅 | E16: 16×80×80×3030
A18: 【玄関】
A19: ニチハ | D19: モエンエクセラード16 | G19: Vｼﾘｰｽﾞ | J19: 金具止め
A20: ﾘｰｶﾞｽﾄｰﾝ調V | E20: EFX3453 | G20: ﾗﾝﾀﾞMGﾊﾟｳﾀﾞｰ
A21: 長尺出隅 | E21: 16×80×80×3030
A24: ｼｰﾘﾝｸﾞ工 | C24: （ﾎﾟｰﾁ軒天・給排気口・アルミ庇 含む） | J24: × | K24: 268 | M24: ｍ
A25: （ブラウン色×≒219ｍ パウダー色×≒49ｍ）
A27: 施工期間
A28: 7月上旬頃 工事予定お願いします

Sheet 換気扇

Sheet 金辰商事

Sheet 杉田エース
